Traceback (most recent call last):
  File "/home/abhishek.anand/Desktop/fst_generator/venv_fst_generator/lib/python3.12/site-packages/selenium/webdriver/common/driver_finder.py", line 64, in _binary_paths
    raise ValueError(f"The path is not a valid file: {path}")
ValueError: The path is not a valid file: ./chromedriver

The above exception was the direct cause of the following exception:

Traceback (most recent call last):
  File "/home/abhishek.anand/Desktop/fst_generator/tests/selenium/test_login.py", line 13, in <module>
    driver = webdriver.Chrome(service=service, options=options)
             ^^^^^^^^^^^^^^^^^^^^^^^^^^^^^^^^^^^^^^^^^^^^^^^^^^
  File "/home/abhishek.anand/Desktop/fst_generator/venv_fst_generator/lib/python3.12/site-packages/selenium/webdriver/chrome/webdriver.py", line 47, in __init__
    super().__init__(
  File "/home/abhishek.anand/Desktop/fst_generator/venv_fst_generator/lib/python3.12/site-packages/selenium/webdriver/chromium/webdriver.py", line 53, in __init__
    if finder.get_browser_path():
       ^^^^^^^^^^^^^^^^^^^^^^^^^
  File "/home/abhishek.anand/Desktop/fst_generator/venv_fst_generator/lib/python3.12/site-packages/selenium/webdriver/common/driver_finder.py", line 47, in get_browser_path
    return self._binary_paths()["browser_path"]
           ^^^^^^^^^^^^^^^^^^^^
  File "/home/abhishek.anand/Desktop/fst_generator/venv_fst_generator/lib/python3.12/site-packages/selenium/webdriver/common/driver_finder.py", line 78, in _binary_paths
    raise NoSuchDriverException(msg) from err
selenium.common.exceptions.NoSuchDriverException: Message: Unable to obtain driver for chrome; For documentation on this error, please visit: https://www.selenium.dev/documentation/webdriver/troubleshooting/errors/driver_location

